[2024-04-22T13:23:10.414+0000] {taskinstance.py:1957} INFO - Dependencies all met for dep_context=non-requeueable deps ti=<TaskInstance: hello_world_dag.hello_world manual__2024-04-22T12:46:44.564732+00:00 [queued]>
[2024-04-22T13:23:10.423+0000] {taskinstance.py:1957} INFO - Dependencies all met for dep_context=requeueable deps ti=<TaskInstance: hello_world_dag.hello_world manual__2024-04-22T12:46:44.564732+00:00 [queued]>
[2024-04-22T13:23:10.424+0000] {taskinstance.py:2171} INFO - Starting attempt 7 of 7
[2024-04-22T13:23:10.436+0000] {taskinstance.py:2192} INFO - Executing <Task(PythonOperator): hello_world> on 2024-04-22 12:46:44.564732+00:00
[2024-04-22T13:23:10.440+0000] {standard_task_runner.py:60} INFO - Started process 1323 to run task
[2024-04-22T13:23:10.443+0000] {standard_task_runner.py:87} INFO - Running: ['***', 'tasks', 'run', 'hello_world_dag', 'hello_world', 'manual__2024-04-22T12:46:44.564732+00:00', '--job-id', '10', '--raw', '--subdir', 'DAGS_FOLDER/hello_world_dag.py', '--cfg-path', '/tmp/tmp66u_qhm0']
[2024-04-22T13:23:10.445+0000] {standard_task_runner.py:88} INFO - Job 10: Subtask hello_world
[2024-04-22T13:23:10.459+0000] {logging_mixin.py:188} WARNING - /home/***/.local/lib/python3.8/site-packages/***/settings.py:195 DeprecationWarning: The sql_alchemy_conn option in [core] has been moved to the sql_alchemy_conn option in [database] - the old setting has been used, but please update your config.
[2024-04-22T13:23:10.491+0000] {task_command.py:423} INFO - Running <TaskInstance: hello_world_dag.hello_world manual__2024-04-22T12:46:44.564732+00:00 [running]> on host c9c55c9ee351
[2024-04-22T13:23:10.556+0000] {taskinstance.py:2481} INFO - Exporting env vars: AIRFLOW_CTX_DAG_OWNER='***' AIRFLOW_CTX_DAG_ID='hello_world_dag' AIRFLOW_CTX_TASK_ID='hello_world' AIRFLOW_CTX_EXECUTION_DATE='2024-04-22T12:46:44.564732+00:00' AIRFLOW_CTX_TRY_NUMBER='7' AIRFLOW_CTX_DAG_RUN_ID='manual__2024-04-22T12:46:44.564732+00:00'
[2024-04-22T13:23:10.557+0000] {uwdr_hook.py:18} INFO - 
    select version()
    
[2024-04-22T13:23:10.566+0000] {taskinstance.py:2699} ERROR - Task failed with exception
Traceback (most recent call last):
  File "/home/airflow/.local/lib/python3.8/site-packages/airflow/models/taskinstance.py", line 433, in _execute_task
    result = execute_callable(context=context, **execute_callable_kwargs)
  File "/home/airflow/.local/lib/python3.8/site-packages/airflow/operators/python.py", line 199, in execute
    return_value = self.execute_callable()
  File "/home/airflow/.local/lib/python3.8/site-packages/airflow/operators/python.py", line 216, in execute_callable
    return self.python_callable(*self.op_args, **self.op_kwargs)
  File "/opt/airflow/dags/hello_world_dag.py", line 35, in hello_world_py
    logger.info(f"Текущая версия ClickHouse: {result[0][0]}")
NameError: name 'logger' is not defined
[2024-04-22T13:23:10.577+0000] {taskinstance.py:1138} INFO - Marking task as FAILED. dag_id=hello_world_dag, task_id=hello_world, execution_date=20240422T124644, start_date=20240422T132310, end_date=20240422T132310
[2024-04-22T13:23:10.589+0000] {standard_task_runner.py:107} ERROR - Failed to execute job 10 for task hello_world (name 'logger' is not defined; 1323)
[2024-04-22T13:23:10.616+0000] {local_task_job_runner.py:234} INFO - Task exited with return code 1
[2024-04-22T13:23:10.634+0000] {taskinstance.py:3281} INFO - 0 downstream tasks scheduled from follow-on schedule check
